# API错误修复总结

## 修复的问题

本次修复解决了两个关键问题：

### 1. 健康检查端点错误
**问题描述**: `/api/v1/health`端点返回500错误，日志显示`NameError: name 'datetime' is not defined`

**解决方案**:
- 在`app/main.py`中添加缺少的`datetime`导入
- 移除原来内联的健康检查端点
- 创建专门的`health.py`端点文件
- 更新API路由配置，注册健康检查路由

### 2. 用户注册API异常处理错误
**问题描述**: `/api/v1/users/register`接口报500内部服务器错误，尤其是当尝试注册已存在的用户时

**错误信息**:
```
RuntimeError: generator didn't stop after throw()
```

**原因分析**:
FastAPI在处理从依赖项(如`Depends(get_db)`)抛出的异常时，遇到了与异常处理上下文管理器相关的问题。这种错误通常在异常处理嵌套不当时出现。

**解决方案**:
- 重构`register_user`函数的异常处理流程
- 将输入验证逻辑(检查邮箱和用户名是否存在)移到try-except块外部
- 只将数据库操作(添加、提交、刷新)放入try块内部
- 移除不必要的嵌套异常处理

## 修改的文件

1. `/backend/app/main.py`
   - 添加datetime导入
   - 移除冗余健康检查端点

2. `/backend/app/api/api_v1/endpoints/health.py`(新建)
   - 创建专门的健康检查API端点

3. `/backend/app/api/api_v1/api.py` 
   - 添加健康检查路由

4. `/backend/app/api/api_v1/endpoints/users.py`
   - 修复注册函数的异常处理机制
   - 重构try-except块结构

## 技术详情

### 异常处理优化

**修改前**:
```python
try:
    # 检查邮箱是否已存在
    if db_user:
        raise HTTPException(...)
    
    # 检查用户名是否已存在
    if db_user:
        raise HTTPException(...)
    
    # 创建新用户
    ...
    
except HTTPException:
    # 重新抛出HTTP异常
    raise
except Exception as e:
    # 处理其他异常
    ...
```

**修改后**:
```python
# 检查邮箱是否已存在
if db_user:
    raise HTTPException(...)

# 检查用户名是否已存在
if db_user:
    raise HTTPException(...)

try:
    # 创建新用户
    ...
    
except Exception as e:
    # 处理其他异常
    ...
```

### 修复后的效果

- 健康检查端点(`/api/v1/health`)能正确返回200状态码
- 用户注册API对已存在的用户/邮箱返回正确的400错误，而不是500
- 提高了系统整体稳定性和错误处理能力

## 测试验证

运行`api_test.py`脚本确认修复有效:
- 健康检查接口返回正确的200状态码和JSON响应
- 注册已存在用户时返回预期的400错误，而不是内部服务器错误 